Workbook

Sheet Membresia - ppta
K1: Markup y costo de la operación
A2: Costos | D2: A encontrar | G2: Con quien competimos? | H2: Jumbo | I2: Frest | K2: Markup | L2: Desc. Jumbo | M2: Desc. Frest | N2: mínimo - cubre picking+pasarela | O2: costo operación | P2: minimo cubre delivery | Q2: operación (+delivery) | U2: 0.12 | V2: % markup (PVP) | Y2: La Vega al Costo
A3: delivery | B3: 2400 | D3: x | E3: % markup (PVP) | G3: precio delivery | H3: 4990 | I3: 3990 | K3: 0.05 | L3: 0.28 | M3: 0.32 | N3: 29000 | O3: =N3-N3/(1+K3)-0.02*N3-800 -> 0.95238095 | U3: 15000 | V3: Mínimo de compra | Y3: - Productos de La Vega de 1° calidad (mucho mejor que el super) al costo
A4: picking | B4: 800 | D4: y | E4: Mínimo de compra | G4: delivery gratis? | H4: Prime, sobre 22K | I4: No | K4: 0.06 | L4: 0.27 | M4: 0.32 | N4: 21900 | O4: =N4-N4/(1+K4)-0.02*N4-800 -> 1.6226415 | U4: 38000 | V4: Monto delivery gratis | W4: ----------------------------------------> | Y4: - 23% menos que el jumbo y 28% menos que frest siempre ("30% menos que verdulerias")
A5: pasarela | B5: 0.02 | D5: z | E5: Mínimo delivery gratis | G5: plazo delivery | H5: desde 30 minutos | I5: desde 90 minutos | K5: 0.07 | L5: 0.26 | M5: 0.31 | N5: 17600 | O5: =N5-N5/(1+K5)-0.02*N5-800 -> -0.59813084 | P5: 72000 | Q5: =P5-P5/(1+K5)-0.02*P5-3200 -> 70.280374 | U5: 2990 | V5: delivery | Y5: - Delivery gratis ilimitado (sobre $35000)
D6: d | E6: Delivery | G6: certeza delivery | H6: ventanas de 2 horas | I6: ventanas de 3 hrs | K6: 0.08 | L6: 0.25 | M6: 0.3 | N6: 14800 | O6: =N6-N6/(1+K6)-0.02*N6-800 -> 0.2962963 | P6: 60000 | Q6: =P6-P6/(1+K6)-0.02*P6-3200 -> 44.444444 | U6: 5500 | V6: monto suscripcion mensual
D7: s | E7: Monto suscripcion mensual | G7: cobertura delivery | H7: RM | I7: No todo RM | K7: 0.1 | L7: 0.24 | M7: 0.29 | N7: 11300 | O7: =N7-N7/(1+K7)-0.02*N7-800 -> 1.2727273 | P7: 46000 | Q7: =P7-P7/(1+K7)-0.02*P7-3200 -> 61.818182 | Y7: Comparación | Z7: Jumbo | AA7: Jumbo Prime | AB7: Frest | AC7: GoodFresh
G8: Mix | H8: Individuales | I8: packs + unitarios | K8: 0.12 | L8: 0.23 | M8: 0.28 | N8: 9200 | O8: =N8-N8/(1+K8)-0.02*N8-800 -> 1.7142857 | P8: 37000 | Q8: =P8-P8/(1+K8)-0.02*P8-3200 -> 24.285714 | Y8: precio productos | Z8: Mercado oriente | AA8: Mercado oriente | AB8: Sobre mercado | AC8: Al costo
G9: Formato | H9: Bolsas | I9: Bolsas | Y9: Diferenciador | Z9: one-stop-shop | AA9: one-stop-shop + delivery gratis | AB9: Calidad | AC9: Calidad + Precio
G10: Diferenciador | H10: one-stop-shop | I10: Calidad | K10: Ahorro del usuario en productos (8% markup) | Y10: precio delivery | Z10: 4990 | AA10: 0 sobre 22 | AB10: 3990 | AC10: 2990
G11: Suscripción | H11: 30.000 6 meses (5.000 mensual ) | I11: no | K11: 0.08 | L11: =L6 -> 0.25 | O11: =M6 -> 0.3 | Y11: plazo delivery | Z11: desde 30 minutos | AA11: desde 30 minutos | AB11: desde 90 minutos | AC11: Nex day
G12: qué incluye | H12: delivery gratis sobre 22.000 | K12: Carro | L12: Ahorro/carro jumbo | M12: 2 ped/mes | N12: 4 ped/mes | O12: Ahorro/carroFrest | P12: 2 ped/mes | Q12: 4 ped/mes | T12: Precio suscripción | U12: N | V12: revenue/ mes | W12: revenue/ año | Y12: certeza delivery | Z12: ventanas de 2 horas | AA12: ventanas de 2 horas | AB12: ventanas de 3 hrs | AC12: Nex day
G13: Precios | I13: más caro que supermercado | K13: 15000 | L13: =K13*$L$11 -> 3750 | M13: =L13*2 -> 7500 | N13: =L13*4 -> 15000 | O13: =K13*$O$11 -> 4500 | P13: =O13*2 -> 9000 | Q13: =O13*4 -> 18000 | T13: 4990 | U13: 2000 | V13: =U13*$T$13 -> 9980000 | W13: =V13*10 -> 99800000 | Y13: cobertura delivery | Z13: RM | AA13: RM | AB13: No todo RM | AC13: RM
K14: 20000 | L14: =K14*$L$11 -> 5000 | M14: =L14*2 -> 10000 | N14: =L14*4 -> 20000 | O14: =K14*$O$11 -> 6000 | P14: =O14*2 -> 12000 | Q14: =O14*4 -> 24000 | U14: 3000 | V14: =U14*$T$13 -> 14970000 | W14: =V14*10 -> 149700000 | Y14: Mix productos | Z14: Individuales - estándar | AA14: Individuales - estándar | AB14: packs + unitarios / más premium o nicho | AC14: packs + unitarios / estaciones
K15: 30000 | L15: =K15*$L$11 -> 7500 | M15: =L15*2 -> 15000 | N15: =L15*4 -> 30000 | O15: =K15*$O$11 -> 9000 | P15: =O15*2 -> 18000 | Q15: =O15*4 -> 36000 | U15: 5000 | V15: =U15*$T$13 -> 24950000 | W15: =V15*10 -> 249500000 | Y15: Formato | Z15: Bolsas | AA15: Bolsas | AB15: Bolsas | AC15: Cajas
G16: Jumo prime | K16: Ahorro del usuario en productos (12% markup) | U16: 6000 | V16: =U16*$T$13 -> 29940000 | W16: =V16*10 -> 299400000 | Y16: Diferenciador | Z16: one-stop-shop | AA16: one-stop-shop + delivery gratis | AB16: Calidad | AC16: Calidad + Precio
G17: "me sale 5000 cada delivery y la sucripcion 5000 por delivery gratis" | K17: 0.12 | L17: =L8 -> 0.23 | O17: =M8 -> 0.28 | U17: 8000 | V17: =U17*$T$13 -> 39920000 | W17: =V17*10 -> 399200000 | Y17: Costo suscripción (mes) | AA17: 5000 | AC17: 4990
G18: comunicación: "delivery gratis ilimitado" | K18: Carro | L18: Ahorro/carro jumbo | M18: 2 ped/mes | N18: 4 ped/mes | O18: Ahorro/carroFrest | P18: 2 ped/mes | Q18: 4 ped/mes | U18: 10000 | V18: =U18*$T$13 -> 49900000 | W18: =V18*10 -> 499000000
G19: letra chica: sobre 22.000 | K19: 15000 | L19: =K19*$L$17 -> 3450 | M19: =L19*2 -> 6900 | N19: =L19*4 -> 13800 | O19: =K19*$O$17 -> 4200 | P19: =O19*2 -> 8400 | Q19: =O19*4 -> 16800
K20: 20000 | L20: =K20*$L$17 -> 4600 | M20: =L20*2 -> 9200 | N20: =L20*4 -> 18400 | O20: =K20*$O$17 -> 5600 | P20: =O20*2 -> 11200 | Q20: =O20*4 -> 22400 | T20: 50000
K21: 30000 | L21: =K21*$L$17 -> 6900 | M21: =L21*2 -> 13800 | N21: =L21*4 -> 27600 | O21: =K21*$O$17 -> 8400 | P21: =O21*2 -> 16800 | Q21: =O21*4 -> 33600
K23: Delivery | L23: 1 pedido | M23: 2 ped/mes | N23: 4 ped/mes
L24: 2990 | M24: =L24*2 -> 5980 | N24: =M24*4 -> 23920

Sheet PPTA
B2: Con quien competimos? | C2: Jumbo | D2: Frest | G2: Objetivo de esta tienda
B3: precio delivery | C3: 4990 | D3: 3990 | G3: Salir del descuento
B4: delivery gratis? | C4: Prime, sobre 22K | D4: No | G4: Controlar stock
B5: plazo delivery | C5: desde 30 minutos | D5: desde 90 minutos | G5: Recurrencia
B6: certeza delivery | C6: ventanas de 2 horas | D6: ventanas de 3 hrs | G6: Que nuestros buyers compren más
B7: cobertura delivery | C7: RM | D7: No todo RM
B8: Mix | C8: Individuales | D8: packs + unitarios
B9: Formato | C9: Bolsas | D9: Bolsas
B10: Diferenciador | C10: one-stop-shop | D10: Calidad
B11: Margen GF igualando precios (Bruto) | C11: 0.31 | D11: 0.32
C14: Propuesta GF Membresía
B15: Margen | C15: 0-10%
B16: Estrategia pricing | C16: Costo + 12%
B17: Mix productos | C17: packs + unitarios
B18: Formato | C18: Cajas
B19: Packaging | C19: Caja que se devuelve
B20: Plazo entrega | C20: Next day
B21: Diferenciador | C21: Calidad y Precio
B22: Beneficio | C22: -23% jumbo -28 frest -15% lider
B23: Costo delivery | C23: 2990
B24: Membresía acceso

Sheet Listado de precios
A1: Producto | B1: Unidad | C1: Cantidad | D1: Precio Distribuidor C/IVA | E1: PVP | F1: Margen | G1: PVP suscripción (+12%) | H1: PVP (+8%) | I1: Lider | J1: Frest | K1: Jumbo | L1: Margen PVP frest | M1: Margen PVP Jumbo | N1: Juan esparraguito | O1: Dif vs lider % | P1: Dif vs Jumbo % | Q1: Link foto | R1: Otro | U1: PVP sus / Lider | V1: PVP sus /Jumbo (12%) | W1: PVP suscipcion - frest (12%) | X1: costo - jumbo | Y1: PVP sus /Jumbo (8%) | Z1: PVP suscipcion - frest (8%)
A2: Acelga | B2: Paquete | C2: 1 | D2: 850 | E2: 1590 | F2: =(E2-D2)/E2 -> 0.46540881 | G2: =D2*1.12 -> 952 | H2: =D2*1.08 -> 918 | I2: 1490 | J2: 1290 | K2: 1590 | L2: =(J2-D2)/J2 -> 0.34108527 | M2: =(K2-D2)/K2 -> 0.46540881 | O2: =(E2-I2)/E2 -> 0.062893082 | P2: =(E2-K2)/E2 -> 0 | Q2: https://cdn.shopify.com/s/files/1/0733/7318/8148/files/acelga.jpg?v=1762371793 | S2: =VLOOKUP(A2,'precios semana 2906'!A:B,2,0) -> 850 | T2: =(S2/D2)-1 -> 0 | U2: =G2/I2-1 -> -0.36107383 | V2: =G2/K2-1 -> -0.40125786 | W2: =G2/J2-1 -> -0.2620155 | X2: =G2-K2 -> -638 | Y2: =(H2/K2)-1 -> -0.42264151 | Z2: =(H2/J2)-1 -> -0.28837209
A3: Ají amarillo (peruano) | B3: Kilo | C3: 0.1 | D3: 700 | E3: 1390 | F3: =(E3-D3)/E3 -> 0.49640288 | G3: =D3*1.12 -> 784 | H3: =D3*1.08 -> 756 | J3: 1196 | L3: =(J3-D3)/J3 -> 0.41471572 | N3: 1390 | O3: =(E3-I3)/E3 -> 1 | P3: =(E3-K3)/E3 -> 1 | Q3: https://cdn.shopify.com/s/files/1/0733/7318/8148/files/ajiamarillo.jpg?v=1762286889 | R3: 1390 | S3: =VLOOKUP(A3,'precios semana 2906'!A:B,2,0) -> 700 | T3: =(S3/D3)-1 -> 0 | W3: =G3/J3-1 -> -0.34448161 | Y3: =(H3/K3)-1 -> #DIV/0! | Z3: =(H3/J3)-1 -> -0.36789298
A4: Ají verde (infierno) | B4: Kilo | C4: 0.2 | D4: 800 | E4: 1100 | F4: =(E4-D4)/E4 -> 0.27272727 | G4: =D4*1.12 -> 896 | H4: =D4*1.08 -> 864 | I4: 1078 | J4: 1112 | K4: 1158 | L4: =(J4-D4)/J4 -> 0.28057554 | M4: =(K4-D4)/K4 -> 0.30915371 | N4: 590 | O4: =(E4-I4)/E4 -> 0.02 | P4: =(E4-K4)/E4 -> -0.052727273 | Q4: https://cdn.shopify.com/s/files/1/0733/7318/8148/files/ajiverde.png?v=1762371744 | S4: =VLOOKUP(A4,'precios semana 2906'!A:B,2,0) -> 800 | T4: =(S4/D4)-1 -> 0 | U4: =G4/I4-1 -> -0.16883117 | V4: =G4/K4-1 -> -0.22625216 | W4: =G4/J4-1 -> -0.1942446 | X4: =G4-K4 -> -262 | Y4: =(H4/K4)-1 -> -0.25388601 | Z4: =(H4/J4)-1 -> -0.22302158
A5: Ajo | B5: Unidad | C5: 1 | D5: 200 | E5: 350 | F5: =(E5-D5)/E5 -> 0.42857143 | G5: =D5*1.12 -> 224 | H5: =D5*1.08 -> 216 | I5: 363 | J5: 300 | K5: 397 | L5: =(J5-D5)/J5 -> 0.33333333 | M5: =(K5-D5)/K5 -> 0.49622166 | N5: 1200 | O5: =(E5-I5)/E5 -> -0.037142857 | P5: =(E5-K5)/E5 -> -0.13428571 | Q5: https://cdn.shopify.com/s/files/1/0733/7318/8148/files/ajo.jpg?v=1762371704 | S5: =VLOOKUP(A5,'precios semana 2906'!A:B,2,0) -> 200 | T5: =(S5/D5)-1 -> 0 | U5: =G5/I5-1 -> -0.38292011 | V5: =G5/K5-1 -> -0.43576826 | W5: =G5/J5-1 -> -0.25333333 | X5: =G5-K5 -> -173 | Y5: =(H5/K5)-1 -> -0.4559194 | Z5: =(H5/J5)-1 -> -0.28
A6: Albahaca | B6: Kilo | C6: 0.05 | D6: 600 | E6: 1490 | F6: =(E6-D6)/E6 -> 0.59731544 | G6: =D6*1.12 -> 672 | H6: =D6*1.08 -> 648 | I6: 1590 | J6: 1490 | K6: 1590 | L6: =(J6-D6)/J6 -> 0.59731544 | M6: =(K6-D6)/K6 -> 0.62264151 | N6: 1690 | O6: =(E6-I6)/E6 -> -0.067114094 | P6: =(E6-K6)/E6 -> -0.067114094 | Q6: https://cdn.shopify.com/s/files/1/0733/7318/8148/files/zoomfotonoticia-129.jpg?v=1762371661 | R6: 845 | S6: =VLOOKUP(A6,'precios semana 2906'!A:B,2,0) -> 600 | T6: =(S6/D6)-1 -> 0 | U6: =G6/I6-1 -> -0.57735849 | V6: =G6/K6-1 -> -0.57735849 | W6: =G6/J6-1 -> -0.54899329 | X6: =G6-K6 -> -918 | Y6: =(H6/K6)-1 -> -0.59245283 | Z6: =(H6/J6)-1 -> -0.56510067
A7: Apio | B7: Unidad | C7: 1 | D7: 1500 | E7: 1990 | F7: =(E7-D7)/E7 -> 0.24623116 | G7: =D7*1.12 -> 1680 | H7: =D7*1.08 -> 1620 | I7: 1000 | J7: 1990 | K7: 1490 | L7: =(J7-D7)/J7 -> 0.24623116 | M7: =(K7-D7)/K7 -> -0.0067114094 | N7: 1990 | O7: =(E7-I7)/E7 -> 0.49748744 | P7: =(E7-K7)/E7 -> 0.25125628 | Q7: https://cdn.shopify.com/s/files/1/0733/7318/8148/files/apio.jpg?v=1762371609 | R7: 1990 | S7: =VLOOKUP(A7,'precios semana 2906'!A:B,2,0) -> 1400 | T7: =(S7/D7)-1 -> -0.066666667 | U7: =G7/I7-1 -> 0.68 | V7: =G7/K7-1 -> 0.12751678 | W7: =G7/J7-1 -> -0.15577889 | X7: =G7-K7 -> 190 | Y7: =(H7/K7)-1 -> 0.087248322 | Z7: =(H7/J7)-1 -> -0.18592965
A8: Alcachofas españolas | B8: Unidad | C8: 1 | D8: 800 | E8: 1390 | F8: =(E8-D8)/E8 -> 0.42446043 | G8: =D8*1.12 -> 896 | H8: =D8*1.08 -> 864 | I8: 790 | J8: 1390 | K8: 790 | L8: =(J8-D8)/J8 -> 0.42446043 | M8: =(K8-D8)/K8 -> -0.012658228 | N8: 1290 | O8: =(E8-I8)/E8 -> 0.43165468 | P8: =(E8-K8)/E8 -> 0.43165468 | Q8: https://cdn.shopify.com/s/files/1/0733/7318/8148/files/alcachofa_espaola_1ce9f8da-7a49-4ca2-9f3c-dad8035d9680.jpg?v=1762273270 | R8: 1290 | S8: =VLOOKUP(A8,'precios semana 2906'!A:B,2,0) -> 800 | T8: =(S8/D8)-1 -> 0 | U8: =G8/I8-1 -> 0.13417722 | V8: =G8/K8-1 -> 0.13417722 | W8: =G8/J8-1 -> -0.35539568 | X8: =G8-K8 -> 106 | Y8: =(H8/K8)-1 -> 0.093670886 | Z8: =(H8/J8)-1 -> -0.37841727
A9: Berenjena | B9: Unidad | C9: 1 | D9: 600 | E9: 890 | F9: =(E9-D9)/E9 -> 0.3258427 | G9: =D9*1.12 -> 672 | H9: =D9*1.08 -> 648 | I9: 790 | J9: 790 | K9: 790 | L9: =(J9-D9)/J9 -> 0.24050633 | M9: =(K9-D9)/K9 -> 0.24050633 | N9: 890 | O9: =(E9-I9)/E9 -> 0.11235955 | P9: =(E9-K9)/E9 -> 0.11235955 | Q9: https://cdn.shopify.com/s/files/1/0733/7318/8148/files/berenjena.jpg?v=1762371565 | R9: 890 | S9: =VLOOKUP(A9,'precios semana 2906'!A:B,2,0) -> 600 | T9: =(S9/D9)-1 -> 0 | U9: =G9/I9-1 -> -0.14936709 | V9: =G9/K9-1 -> -0.14936709 | W9: =G9/J9-1 -> -0.14936709 | X9: =G9-K9 -> -118 | Y9: =(H9/K9)-1 -> -0.17974684 | Z9: =(H9/J9)-1 -> -0.17974684
A10: Berros | B10: Kilo | C10: 0.05 | D10: 700 | E10: 1050 | F10: =(E10-D10)/E10 -> 0.33333333 | G10: =D10*1.12 -> 784 | H10: =D10*1.08 -> 756 | I10: 423 | J10: 663 | K10: 1050 | L10: =(J10-D10)/J10 -> -0.055806938 | M10: =(K10-D10)/K10 -> 0.33333333 | N10: 2690 | O10: =(E10-I10)/E10 -> 0.59714286 | P10: =(E10-K10)/E10 -> 0 | Q10: https://cdn.shopify.com/s/files/1/0733/7318/8148/files/berro.png?v=1762371522 | S10: =VLOOKUP(A10,'precios semana 2906'!A:B,2,0) -> 700 | T10: =(S10/D10)-1 -> 0 | U10: =G10/I10-1 -> 0.8534279 | V10: =G10/K10-1 -> -0.25333333 | W10: =G10/J10-1 -> 0.18250377 | X10: =G10-K10 -> -266 | Y10: =(H10/K10)-1 -> -0.28 | Z10: =(H10/J10)-1 -> 0.14027149
A11: Betarraga | B11: Paquete | C11: 1 | D11: 1000 | E11: 2250 | F11: =(E11-D11)/E11 -> 0.55555556 | G11: =D11*1.12 -> 1120 | H11: =D11*1.08 -> 1080 | I11: 1390 | J11: 2250 | K11: 1490 | L11: =(J11-D11)/J11 -> 0.55555556 | M11: =(K11-D11)/K11 -> 0.32885906 | N11: 2190 | O11: =(E11-I11)/E11 -> 0.38222222 | P11: =(E11-K11)/E11 -> 0.33777778 | Q11: https://cdn.shopify.com/s/files/1/0733/7318/8148/files/betarraga.jpg?v=1762371470 | R11: 2190 | S11: =VLOOKUP(A11,'precios semana 2906'!A:B,2,0) -> 1000 | T11: =(S11/D11)-1 -> 0 | U11: =G11/I11-1 -> -0.1942446 | V11: =G11/K11-1 -> -0.24832215 | W11: =G11/J11-1 -> -0.50222222 | X11: =G11-K11 -> -370 | Y11: =(H11/K11)-1 -> -0.27516779 | Z11: =(H11/J11)-1 -> -0.52
A12: Brocoli | B12: Unidad | C12: 1 | D12: 1400 | E12: 1990 | F12: =(E12-D12)/E12 -> 0.29648241 | G12: =D12*1.12 -> 1568 | H12: =D12*1.08 -> 1512 | I12: 1590 | J12: 1990 | K12: 1590 | L12: =(J12-D12)/J12 -> 0.29648241 | M12: =(K12-D12)/K12 -> 0.11949686 | N12: 1990 | O12: =(E12-I12)/E12 -> 0.20100503 | P12: =(E12-K12)/E12 -> 0.20100503 | Q12: https://cdn.shopify.com/s/files/1/0733/7318/8148/files/brocoli.jpg?v=1762371426 | R12: 1990 | S12: =VLOOKUP(A12,'precios semana 2906'!A:B,2,0) -> 1400 | T12: =(S12/D12)-1 -> 0 | U12: =G12/I12-1 -> -0.013836478 | V12: =G12/K12-1 -> -0.013836478 | W12: =G12/J12-1 -> -0.2120603 | X12: =G12-K12 -> -22 | Y12: =(H12/K12)-1 -> -0.049056604 | Z12: =(H12/J12)-1 -> -0.24020101
A13: Bruselas | B13: Kilo | C13: 0.5 | D13: 1200 | E13: 3690 | F13: =(E13-D13)/E13 -> 0.67479675 | G13: =D13*1.12 -> 1344 | H13: =D13*1.08 -> 1296 | I13: 3190 | J13: 3690 | K13: 3290 | L13: =(J13-D13)/J13 -> 0.67479675 | M13: =(K13-D13)/K13 -> 0.63525836 | N13: 2490 | O13: =(E13-I13)/E13 -> 0.13550136 | P13: =(E13-K13)/E13 -> 0.10840108 | Q13: https://cdn.shopify.com/s/files/1/0733/7318/8148/files/brusela_7ad88d5e-8c5a-44de-b1b8-f5077d48c88a.jpg?v=1770824864 | S13: =VLOOKUP(A13,'precios semana 2906'!A:B,2,0) -> 1200 | T13: =(S13/D13)-1 -> 0 | U13: =G13/I13-1 -> -0.57868339 | V13: =G13/K13-1 -> -0.59148936 | W13: =G13/J13-1 -> -0.63577236 | X13: =G13-K13 -> -1946 | Y13: =(H13/K13)-1 -> -0.60607903 | Z13: =(H13/J13)-1 -> -0.64878049
A14: Camote Morado | B14: Kilo | C14: 0.5 | D14: 1000 | E14: 1545 | F14: =(E14-D14)/E14 -> 0.35275081 | G14: =D14*1.12 -> 1120 | H14: =D14*1.08 -> 1080 | I14: 1545 | J14: 1495 | K14: 1545 | L14: =(J14-D14)/J14 -> 0.33110368 | M14: =(K14-D14)/K14 -> 0.35275081 | N14: 1395 | O14: =(E14-I14)/E14 -> 0 | P14: =(E14-K14)/E14 -> 0 | Q14: https://cdn.shopify.com/s/files/1/0733/7318/8148/files/camotemorado.jpg?v=1762371378 | S14: =VLOOKUP(A14,'precios semana 2906'!A:B,2,0) -> 1000 | T14: =(S14/D14)-1 -> 0 | U14: =G14/I14-1 -> -0.27508091 | V14: =G14/K14-1 -> -0.27508091 | W14: =G14/J14-1 -> -0.25083612 | X14: =G14-K14 -> -425 | Y14: =(H14/K14)-1 -> -0.30097087 | Z14: =(H14/J14)-1 -> -0.27759197
A15: Cebolla | B15: Unidad | C15: 1 | D15: 250 | E15: 450 | F15: =(E15-D15)/E15 -> 0.44444444 | G15: =D15*1.12 -> 280 | H15: =D15*1.08 -> 270 | I15: =1690/3.5 -> 482.85714 | J15: 430 | K15: =1690/3.5 -> 482.85714 | L15: =(J15-D15)/J15 -> 0.41860465 | M15: =(K15-D15)/K15 -> 0.48224852 | N15: 795 | O15: =(E15-I15)/E15 -> -0.073015873 | P15: =(E15-K15)/E15 -> -0.073015873 | Q15: https://cdn.shopify.com/s/files/1/0733/7318/8148/files/cebolla.jpg?v=1762371345 | S15: =VLOOKUP(A15,'precios semana 2906'!A:B,2,0) -> 250 | T15: =(S15/D15)-1 -> 0 | U15: =G15/I15-1 -> -0.42011834 | V15: =G15/K15-1 -> -0.42011834 | W15: =G15/J15-1 -> -0.34883721 | X15: =G15-K15 -> -202.85714 | Y15: =(H15/K15)-1 -> -0.4408284 | Z15: =(H15/J15)-1 -> -0.37209302
A16: Cebolla morada | B16: Unidad | C16: 1 | D16: 300 | E16: 570 | F16: =(E16-D16)/E16 -> 0.47368421 | G16: =D16*1.12 -> 336 | H16: =D16*1.08 -> 324 | I16: =1990/3.5 -> 568.57143 | J16: 463 | K16: =1990/3.5 -> 568.57143 | L16: =(J16-D16)/J16 -> 0.35205184 | M16: =(K16-D16)/K16 -> 0.47236181 | N16: 995 | O16: =(E16-I16)/E16 -> 0.0025062657 | P16: =(E16-K16)/E16 -> 0.0025062657 | Q16: https://cdn.shopify.com/s/files/1/0733/7318/8148/files/cebollamorada.jpg?v=1762371301 | S16: =VLOOKUP(A16,'precios semana 2906'!A:B,2,0) -> 300 | T16: =(S16/D16)-1 -> 0 | U16: =G16/I16-1 -> -0.40904523 | V16: =G16/K16-1 -> -0.40904523 | W16: =G16/J16-1 -> -0.27429806 | X16: =G16-K16 -> -232.57143 | Y16: =(H16/K16)-1 -> -0.43015075 | Z16: =(H16/J16)-1 -> -0.30021598
A17: Cebollín | B17: Paquete | C17: 1 | D17: 700 | E17: 1190 | F17: =(E17-D17)/E17 -> 0.41176471 | G17: =D17*1.12 -> 784 | H17: =D17*1.08 -> 756 | I17: 1550 | J17: 1190 | K17: 1590 | L17: =(J17-D17)/J17 -> 0.41176471 | M17: =(K17-D17)/K17 -> 0.55974843 | N17: 990 | O17: =(E17-I17)/E17 -> -0.30252101 | P17: =(E17-K17)/E17 -> -0.33613445 | Q17: https://cdn.shopify.com/s/files/1/0733/7318/8148/files/cebollin.jpg?v=1762371254 | S17: =VLOOKUP(A17,'precios semana 2906'!A:B,2,0) -> 700 | T17: =(S17/D17)-1 -> 0 | U17: =G17/I17-1 -> -0.49419355 | V17: =G17/K17-1 -> -0.50691824 | W17: =G17/J17-1 -> -0.34117647 | X17: =G17-K17 -> -806 | Y17: =(H17/K17)-1 -> -0.5245283 | Z17: =(H17/J17)-1 -> -0.36470588
A18: Champiñon | B18: Bandeja | C18: 1 | D18: 1500 | E18: 2190 | F18: =(E18-D18)/E18 -> 0.31506849 | G18: =D18*1.12 -> 1680 | H18: =D18*1.08 -> 1620 | I18: 1590 | J18: 1990 | K18: 1650 | L18: =(J18-D18)/J18 -> 0.24623116 | M18: =(K18-D18)/K18 -> 0.090909091 | N18: 2190 | O18: =(E18-I18)/E18 -> 0.2739726 | P18: =(E18-K18)/E18 -> 0.24657534 | Q18: https://cdn.shopify.com/s/files/1/0733/7318/8148/files/champinon.png?v=1762371200 | R18: 2190 | S18: =VLOOKUP(A18,'precios semana 2906'!A:B,2,0) -> 1500 | T18: =(S18/D18)-1 -> 0 | U18: =G18/I18-1 -> 0.056603774 | V18: =G18/K18-1 -> 0.018181818 | W18: =G18/J18-1 -> -0.15577889 | X18: =G18-K18 -> 30 | Y18: =(H18/K18)-1 -> -0.018181818 | Z18: =(H18/J18)-1 -> -0.18592965
A19: Choclo americano | B19: Unidad | C19: 1 | D19: 700 | E19: 990 | F19: =(E19-D19)/E19 -> 0.29292929 | G19: =D19*1.12 -> 784 | H19: =D19*1.08 -> 756 | I19: 898 | J19: 900 | K19: 925 | L19: =(J19-D19)/J19 -> 0.22222222 | M19: =(K19-D19)/K19 -> 0.24324324 | N19: 990 | O19: =(E19-I19)/E19 -> 0.092929293 | P19: =(E19-K19)/E19 -> 0.065656566 | Q19: https://cdn.shopify.com/s/files/1/0733/7318/8148/files/chocloamericano.jpg?v=1762371104 | R19: 990 | S19: =VLOOKUP(A19,'precios semana 2906'!A:B,2,0) -> 800 | T19: =(S19/D19)-1 -> 0.14285714 | U19: =G19/I19-1 -> -0.12694878 | V19: =G19/K19-1 -> -0.15243243 | W19: =G19/J19-1 -> -0.12888889 | X19: =G19-K19 -> -141 | Y19: =(H19/K19)-1 -> -0.1827027 | Z19: =(H19/J19)-1 -> -0.16
A20: Ciboulette | B20: Paquete | C20: 1 | D20: 350 | E20: 740 | F20: =(E20-D20)/E20 -> 0.52702703 | G20: =D20*1.12 -> 392 | H20: =D20*1.08 -> 378 | I20: 690 | J20: 500 | K20: 740 | L20: =(J20-D20)/J20 -> 0.3 | M20: =(K20-D20)/K20 -> 0.52702703 | N20: 790 | O20: =(E20-I20)/E20 -> 0.067567568 | P20: =(E20-K20)/E20 -> 0 | Q20: https://cdn.shopify.com/s/files/1/0733/7318/8148/files/ciboulette.jpg?v=1762371149 | R20: 790 | S20: =VLOOKUP(A20,'precios semana 2906'!A:B,2,0) -> 350 | T20: =(S20/D20)-1 -> 0 | U20: =G20/I20-1 -> -0.43188406 | V20: =G20/K20-1 -> -0.47027027 | W20: =G20/J20-1 -> -0.216 | X20: =G20-K20 -> -348 | Y20: =(H20/K20)-1 -> -0.48918919 | Z20: =(H20/J20)-1 -> -0.244
A21: Cilantro | B21: Paquete | C21: 1 | D21: 600 | E21: 1290 | F21: =(E21-D21)/E21 -> 0.53488372 | G21: =D21*1.12 -> 672 | H21: =D21*1.08 -> 648 | I21: 950 | J21: 990 | K21: 990 | L21: =(J21-D21)/J21 -> 0.39393939 | M21: =(K21-D21)/K21 -> 0.39393939 | N21: 1290 | O21: =(E21-I21)/E21 -> 0.26356589 | P21: =(E21-K21)/E21 -> 0.23255814 | Q21: https://cdn.shopify.com/s/files/1/0733/7318/8148/files/cilantro.jpg?v=1762371069 | R21: 1290 | S21: =VLOOKUP(A21,'precios semana 2906'!A:B,2,0) -> 650 | T21: =(S21/D21)-1 -> 0.083333333 | U21: =G21/I21-1 -> -0.29263158 | V21: =G21/K21-1 -> -0.32121212 | W21: =G21/J21-1 -> -0.32121212 | X21: =G21-K21 -> -318 | Y21: =(H21/K21)-1 -> -0.34545455 | Z21: =(H21/J21)-1 -> -0.34545455
A22: Coliflor | B22: Unidad | C22: 1 | D22: 1500 | E22: 2490 | F22: =(E22-D22)/E22 -> 0.39759036 | G22: =D22*1.12 -> 1680 | H22: =D22*1.08 -> 1620 | I22: 1590 | J22: 2490 | K22: 1690 | L22: =(J22-D22)/J22 -> 0.39759036 | M22: =(K22-D22)/K22 -> 0.11242604 | N22: 1990 | O22: =(E22-I22)/E22 -> 0.36144578 | P22: =(E22-K22)/E22 -> 0.32128514 | Q22: https://cdn.shopify.com/s/files/1/0733/7318/8148/files/coliflor.jpg?v=1762371015 | S22: =VLOOKUP(A22,'precios semana 2906'!A:B,2,0) -> 1500 | T22: =(S22/D22)-1 -> 0 | U22: =G22/I22-1 -> 0.056603774 | V22: =G22/K22-1 -> -0.0059171598 | W22: =G22/J22-1 -> -0.3253012 | X22: =G22-K22 -> -10 | Y22: =(H22/K22)-1 -> -0.041420118 | Z22: =(H22/J22)-1 -> -0.34939759
A23: Diente de dragon | B23: Kilo | C23: 0.2 | D23: 650 | E23: 1060 | F23: =(E23-D23)/E23 -> 0.38679245 | G23: =D23*1.12 -> 728 | H23: =D23*1.08 -> 702 | I23: 990 | J23: 792 | K23: 1060 | L23: =(J23-D23)/J23 -> 0.17929293 | M23: =(K23-D23)/K23 -> 0.38679245 | N23: no hay | O23: =(E23-I23)/E23 -> 0.066037736 | P23: =(E23-K23)/E23 -> 0 | Q23: https://cdn.shopify.com/s/files/1/0733/7318/8148/files/diente-de-dragon.jpg?v=1762286722 | S23: =VLOOKUP(A23,'precios semana 2906'!A:B,2,0) -> 800 | T23: =(S23/D23)-1 -> 0.23076923 | U23: =G23/I23-1 -> -0.26464646 | V23: =G23/K23-1 -> -0.31320755 | W23: =G23/J23-1 -> -0.080808081 | X23: =G23-K23 -> -332 | Y23: =(H23/K23)-1 -> -0.33773585 | Z23: =(H23/J23)-1 -> -0.11363636
A24: Esparragos | B24: Kilo | C24: 0.3 | D24: 3500 | E24: 5290 | F24: =(E24-D24)/E24 -> 0.33837429 | G24: =D24*1.12 -> 3920 | H24: =D24*1.08 -> 3780 | I24: 4190 | J24: 5290 | K24: 4610 | L24: =(J24-D24)/J24 -> 0.33837429 | M24: =(K24-D24)/K24 -> 0.24078091 | N24: no hay | O24: =(E24-I24)/E24 -> 0.20793951 | P24: =(E24-K24)/E24 -> 0.12854442 | Q24: https://cdn.shopify.com/s/files/1/0733/7318/8148/files/esparragos-verdes.jpg?v=1774095995 | S24: =VLOOKUP(A24,'precios semana 2906'!A:B,2,0) -> 3500 | T24: =(S24/D24)-1 -> 0 | U24: =G24/I24-1 -> -0.064439141 | V24: =G24/K24-1 -> -0.14967462 | W24: =G24/J24-1 -> -0.25897921 | X24: =G24-K24 -> -690 | Y24: =(H24/K24)-1 -> -0.18004338 | Z24: =(H24/J24)-1 -> -0.28544423
A25: Jengibre | B25: Kilo | C25: 0.1 | D25: 400 | E25: 1490 | F25: =(E25-D25)/E25 -> 0.73154362 | G25: =D25*1.12 -> 448 | H25: =D25*1.08 -> 432 | I25: 1490 | J25: 1380 | K25: 1590 | L25: =(J25-D25)/J25 -> 0.71014493 | M25: =(K25-D25)/K25 -> 0.74842767 | N25: 1390 | O25: =(E25-I25)/E25 -> 0 | P25: =(E25-K25)/E25 -> -0.067114094 | Q25: https://cdn.shopify.com/s/files/1/0733/7318/8148/files/jengibre.jpg?v=1762370932 | R25: 1390 | S25: =VLOOKUP(A25,'precios semana 2906'!A:B,2,0) -> 400 | T25: =(S25/D25)-1 -> 0 | U25: =G25/I25-1 -> -0.69932886 | V25: =G25/K25-1 -> -0.71823899 | W25: =G25/J25-1 -> -0.67536232 | X25: =G25-K25 -> -1142 | Y25: =(H25/K25)-1 -> -0.72830189 | Z25: =(H25/J25)-1 -> -0.68695652
A26: Lechuga costina | B26: Unidad | C26: 1 | D26: 1000 | E26: 1490 | F26: =(E26-D26)/E26 -> 0.32885906 | G26: =D26*1.12 -> 1120 | H26: =D26*1.08 -> 1080 | I26: 1290 | J26: 1390 | K26: 1420 | L26: =(J26-D26)/J26 -> 0.28057554 | M26: =(K26-D26)/K26 -> 0.29577465 | N26: 1490 | O26: =(E26-I26)/E26 -> 0.13422819 | P26: =(E26-K26)/E26 -> 0.046979866 | Q26: https://cdn.shopify.com/s/files/1/0733/7318/8148/files/lechugacostina.png?v=1762370884 | R26: 1490 | S26: =VLOOKUP(A26,'precios semana 2906'!A:B,2,0) -> 1000 | T26: =(S26/D26)-1 -> 0 | U26: =G26/I26-1 -> -0.13178295 | V26: =G26/K26-1 -> -0.21126761 | W26: =G26/J26-1 -> -0.1942446 | X26: =G26-K26 -> -300 | Y26: =(H26/K26)-1 -> -0.23943662 | Z26: =(H26/J26)-1 -> -0.22302158
A27: Lechuga escarola | B27: Unidad | C27: 1 | D27: 800 | E27: 1460 | F27: =(E27-D27)/E27 -> 0.45205479 | G27: =D27*1.12 -> 896 | H27: =D27*1.08 -> 864 | I27: 1290 | J27: 1290 | K27: 1460 | L27: =(J27-D27)/J27 -> 0.37984496 | M27: =(K27-D27)/K27 -> 0.45205479 | N27: 1490 | O27: =(E27-I27)/E27 -> 0.11643836 | P27: =(E27-K27)/E27 -> 0 | Q27: https://cdn.shopify.com/s/files/1/0733/7318/8148/files/lechugaescarola.jpg?v=1762370847 | R27: 1490 | S27: =VLOOKUP(A27,'precios semana 2906'!A:B,2,0) -> 800 | T27: =(S27/D27)-1 -> 0 | U27: =G27/I27-1 -> -0.30542636 | V27: =G27/K27-1 -> -0.38630137 | W27: =G27/J27-1 -> -0.30542636 | X27: =G27-K27 -> -564 | Y27: =(H27/K27)-1 -> -0.40821918 | Z27: =(H27/J27)-1 -> -0.33023256
A28: Lechuga española | B28: Unidad | C28: 1 | D28: 800 | E28: 1890 | F28: =(E28-D28)/E28 -> 0.57671958 | G28: =D28*1.12 -> 896 | H28: =D28*1.08 -> 864 | I28: 1590 | J28: 1890 | K28: 1740 | L28: =(J28-D28)/J28 -> 0.57671958 | M28: =(K28-D28)/K28 -> 0.54022989 | N28: 1890 | O28: =(E28-I28)/E28 -> 0.15873016 | P28: =(E28-K28)/E28 -> 0.079365079 | Q28: https://cdn.shopify.com/s/files/1/0733/7318/8148/files/lechugaespanola.jpg?v=1762370805 | R28: 1890 | S28: =VLOOKUP(A28,'precios semana 2906'!A:B,2,0) -> 800 | T28: =(S28/D28)-1 -> 0 | U28: =G28/I28-1 -> -0.43647799 | V28: =G28/K28-1 -> -0.48505747 | W28: =G28/J28-1 -> -0.52592593 | X28: =G28-K28 -> -844 | Y28: =(H28/K28)-1 -> -0.50344828 | Z28: =(H28/J28)-1 -> -0.54285714
A29: Lechuga Francesa | B29: Unidad | C29: 1 | D29: 800 | E29: 1290 | F29: =(E29-D29)/E29 -> 0.37984496 | G29: =D29*1.12 -> 896 | H29: =D29*1.08 -> 864 | I29: 1290 | J29: 1090 | K29: 1250 | L29: =(J29-D29)/J29 -> 0.26605505 | M29: =(K29-D29)/K29 -> 0.36 | N29: no hay | O29: =(E29-I29)/E29 -> 0 | P29: =(E29-K29)/E29 -> 0.031007752 | Q29: https://cdn.shopify.com/s/files/1/0733/7318/8148/files/lechugafrancesa.jpg?v=1762370766 | S29: =VLOOKUP(A29,'precios semana 2906'!A:B,2,0) -> 800 | T29: =(S29/D29)-1 -> 0 | U29: =G29/I29-1 -> -0.30542636 | V29: =G29/K29-1 -> -0.2832 | W29: =G29/J29-1 -> -0.17798165 | X29: =G29-K29 -> -354 | Y29: =(H29/K29)-1 -> -0.3088 | Z29: =(H29/J29)-1 -> -0.20733945
A30: Lechuga Marina | B30: Unidad | C30: 1 | D30: 800 | E30: 1290 | F30: =(E30-D30)/E30 -> 0.37984496 | G30: =D30*1.12 -> 896 | H30: =D30*1.08 -> 864 | I30: 1290 | J30: 1090 | K30: 1360 | L30: =(J30-D30)/J30 -> 0.26605505 | M30: =(K30-D30)/K30 -> 0.41176471 | N30: no hay | O30: =(E30-I30)/E30 -> 0 | P30: =(E30-K30)/E30 -> -0.054263566 | Q30: https://cdn.shopify.com/s/files/1/0733/7318/8148/files/lechugamarina.png?v=1762370725 | S30: =VLOOKUP(A30,'precios semana 2906'!A:B,2,0) -> 800 | T30: =(S30/D30)-1 -> 0 | U30: =G30/I30-1 -> -0.30542636 | V30: =G30/K30-1 -> -0.34117647 | W30: =G30/J30-1 -> -0.17798165 | X30: =G30-K30 -> -464 | Y30: =(H30/K30)-1 -> -0.36470588 | Z30: =(H30/J30)-1 -> -0.20733945
A31: Lechuga hidroponica | B31: Unidad | C31: 1 | D31: 900 | E31: 1890 | F31: =(E31-D31)/E31 -> 0.52380952 | G31: =D31*1.12 -> 1008 | H31: =D31*1.08 -> 972 | I31: 1590 | J31: 1690 | K31: 1740 | L31: =(J31-D31)/J31 -> 0.46745562 | M31: =(K31-D31)/K31 -> 0.48275862 | N31: 1890 | O31: =(E31-I31)/E31 -> 0.15873016 | P31: =(E31-K31)/E31 -> 0.079365079 | Q31: https://cdn.shopify.com/s/files/1/0733/7318/8148/files/2076542.jpg?v=1762286622 | R31: 1890 | S31: =VLOOKUP(A31,'precios semana 2906'!A:B,2,0) -> 900 | T31: =(S31/D31)-1 -> 0 | U31: =G31/I31-1 -> -0.36603774 | V31: =G31/K31-1 -> -0.42068966 | W31: =G31/J31-1 -> -0.4035503 | X31: =G31-K31 -> -732 | Y31: =(H31/K31)-1 -> -0.44137931 | Z31: =(H31/J31)-1 -> -0.42485207
A32: Menta | B32: Kilo | C32: 0.05 | D32: 480 | E32: 990 | F32: =(E32-D32)/E32 -> 0.51515152 | G32: =D32*1.12 -> 537.6 | H32: =D32*1.08 -> 518.4 | I32: 990 | J32: 990 | K32: 1050 | L32: =(J32-D32)/J32 -> 0.51515152 | M32: =(K32-D32)/K32 -> 0.54285714 | N32: 2690 | O32: =(E32-I32)/E32 -> 0 | P32: =(E32-K32)/E32 -> -0.060606061 | Q32: https://cdn.shopify.com/s/files/1/0733/7318/8148/files/menta.jpg?v=1762370549 | R32: 1345 | S32: =VLOOKUP(A32,'precios semana 2906'!A:B,2,0) -> 480 | T32: =(S32/D32)-1 -> 0 | U32: =G32/I32-1 -> -0.4569697 | V32: =G32/K32-1 -> -0.488 | W32: =G32/J32-1 -> -0.4569697 | X32: =G32-K32 -> -512.4 | Y32: =(H32/K32)-1 -> -0.50628571 | Z32: =(H32/J32)-1 -> -0.47636364
A33: Papa | B33: Kilo | C33: 1 | D33: 850 | E33: 1590 | F33: =(E33-D33)/E33 -> 0.46540881 | G33: =D33*1.12 -> 952 | H33: =D33*1.08 -> 918 | I33: 1590 | J33: 1090 | K33: 1590 | L33: =(J33-D33)/J33 -> 0.22018349 | M33: =(K33-D33)/K33 -> 0.46540881 | N33: 795 | O33: =(E33-I33)/E33 -> 0 | P33: =(E33-K33)/E33 -> 0 | Q33: https://cdn.shopify.com/s/files/1/0733/7318/8148/files/papasemillon_744a31b4-760a-4b2c-ba89-e2fd58430be6.jpg?v=1762273302 | R33: 1590 | S33: =VLOOKUP(A33,'precios semana 2906'!A:B,2,0) -> 850 | T33: =(S33/D33)-1 -> 0 | U33: =G33/I33-1 -> -0.40125786 | V33: =G33/K33-1 -> -0.40125786 | W33: =G33/J33-1 -> -0.1266055 | X33: =G33-K33 -> -638 | Y33: =(H33/K33)-1 -> -0.42264151 | Z33: =(H33/J33)-1 -> -0.15779817
A34: Pepinos | B34: Unidad | C34: 1 | D34: 650 | E34: 790 | F34: =(E34-D34)/E34 -> 0.17721519 | G34: =D34*1.12 -> 728 | H34: =D34*1.08 -> 702 | I34: 720 | J34: 790 | K34: 750 | L34: =(J34-D34)/J34 -> 0.17721519 | M34: =(K34-D34)/K34 -> 0.13333333 | N34: 790 | O34: =(E34-I34)/E34 -> 0.088607595 | P34: =(E34-K34)/E34 -> 0.050632911 | Q34: https://cdn.shopify.com/s/files/1/0733/7318/8148/files/pepino.jpg?v=1762370475 | R34: 790 | S34: =VLOOKUP(A34,'precios semana 2906'!A:B,2,0) -> 650 | T34: =(S34/D34)-1 -> 0 | U34: =G34/I34-1 -> 0.011111111 | V34: =G34/K34-1 -> -0.029333333 | W34: =G34/J34-1 -> -0.078481013 | X34: =G34-K34 -> -22 | Y34: =(H34/K34)-1 -> -0.064 | Z34: =(H34/J34)-1 -> -0.11139241
A35: Perejil | B35: Paquete | C35: 1 | D35: 600 | E35: 990 | F35: =(E35-D35)/E35 -> 0.39393939 | G35: =D35*1.12 -> 672 | H35: =D35*1.08 -> 648 | I35: 630 | J35: 990 | K35: 650 | L35: =(J35-D35)/J35 -> 0.39393939 | M35: =(K35-D35)/K35 -> 0.076923077 | N35: 1250 | O35: =(E35-I35)/E35 -> 0.36363636 | P35: =(E35-K35)/E35 -> 0.34343434 | Q35: https://cdn.shopify.com/s/files/1/0733/7318/8148/files/perejil.jpg?v=1762370436 | S35: =VLOOKUP(A35,'precios semana 2906'!A:B,2,0) -> 700 | T35: =(S35/D35)-1 -> 0.16666667 | U35: =G35/I35-1 -> 0.066666667 | V35: =G35/K35-1 -> 0.033846154 | W35: =G35/J35-1 -> -0.32121212 | X35: =G35-K35 -> 22 | Y35: =(H35/K35)-1 -> -0.0030769231 | Z35: =(H35/J35)-1 -> -0.34545455
A36: Pimentón amarillo | B36: Unidad | C36: 1 | D36: 1000 | E36: 1690 | F36: =(E36-D36)/E36 -> 0.40828402 | G36: =D36*1.12 -> 1120 | H36: =D36*1.08 -> 1080 | I36: 1690 | J36: 1490 | K36: 1790 | L36: =(J36-D36)/J36 -> 0.32885906 | M36: =(K36-D36)/K36 -> 0.44134078 | N36: no hay | O36: =(E36-I36)/E36 -> 0 | P36: =(E36-K36)/E36 -> -0.059171598 | Q36: https://cdn.shopify.com/s/files/1/0733/7318/8148/files/pimentonamarillo.jpg?v=1762370398 | S36: =VLOOKUP(A36,'precios semana 2906'!A:B,2,0) -> 1000 | T36: =(S36/D36)-1 -> 0 | U36: =G36/I36-1 -> -0.33727811 | V36: =G36/K36-1 -> -0.37430168 | W36: =G36/J36-1 -> -0.24832215 | X36: =G36-K36 -> -670 | Y36: =(H36/K36)-1 -> -0.39664804 | Z36: =(H36/J36)-1 -> -0.27516779
A37: Pimentón rojo | B37: Unidad | C37: 1 | D37: 1000 | E37: 1690 | F37: =(E37-D37)/E37 -> 0.40828402 | G37: =D37*1.12 -> 1120 | H37: =D37*1.08 -> 1080 | I37: 1690 | J37: 1490 | K37: 1790 | L37: =(J37-D37)/J37 -> 0.32885906 | M37: =(K37-D37)/K37 -> 0.44134078 | N37: 1790 | O37: =(E37-I37)/E37 -> 0 | P37: =(E37-K37)/E37 -> -0.059171598 | Q37: https://cdn.shopify.com/s/files/1/0733/7318/8148/files/pimentonrojo.jpg?v=1762370356 | R37: 1790 | S37: =VLOOKUP(A37,'precios semana 2906'!A:B,2,0) -> 800 | T37: =(S37/D37)-1 -> -0.2 | U37: =G37/I37-1 -> -0.33727811 | V37: =G37/K37-1 -> -0.37430168 | W37: =G37/J37-1 -> -0.24832215 | X37: =G37-K37 -> -670 | Y37: =(H37/K37)-1 -> -0.39664804 | Z37: =(H37/J37)-1 -> -0.27516779
A38: Pimentón verde | B38: Unidad | C38: 1 | D38: 700 | E38: 1190 | F38: =(E38-D38)/E38 -> 0.41176471 | G38: =D38*1.12 -> 784 | H38: =D38*1.08 -> 756 | I38: 950 | J38: 990 | K38: 990 | L38: =(J38-D38)/J38 -> 0.29292929 | M38: =(K38-D38)/K38 -> 0.29292929 | N38: 1190 | O38: =(E38-I38)/E38 -> 0.20168067 | P38: =(E38-K38)/E38 -> 0.16806723 | Q38: https://cdn.shopify.com/s/files/1/0733/7318/8148/files/pimentonverde.jpg?v=1762370310 | R38: 1190 | S38: =VLOOKUP(A38,'precios semana 2906'!A:B,2,0) -> 700 | T38: =(S38/D38)-1 -> 0 | U38: =G38/I38-1 -> -0.17473684 | V38: =G38/K38-1 -> -0.20808081 | W38: =G38/J38-1 -> -0.20808081 | X38: =G38-K38 -> -206 | Y38: =(H38/K38)-1 -> -0.23636364 | Z38: =(H38/J38)-1 -> -0.23636364
A39: Porotos verdes | B39: Kilo | C39: 0.5 | D39: 1600 | E39: 2190 | F39: =(E39-D39)/E39 -> 0.26940639 | G39: =D39*1.12 -> 1792 | H39: =D39*1.08 -> 1728 | I39: 995 | J39: 2190 | K39: 1995 | L39: =(J39-D39)/J39 -> 0.26940639 | M39: =(K39-D39)/K39 -> 0.19799499 | N39: no hay | O39: =(E39-I39)/E39 -> 0.5456621 | P39: =(E39-K39)/E39 -> 0.089041096 | Q39: https://cdn.shopify.com/s/files/1/0733/7318/8148/files/poroto-verde.jpg?v=1762286507 | S39: =VLOOKUP(A39,'precios semana 2906'!A:B,2,0) -> 1600 | T39: =(S39/D39)-1 -> 0 | U39: =G39/I39-1 -> 0.80100503 | V39: =G39/K39-1 -> -0.10175439 | W39: =G39/J39-1 -> -0.18173516 | X39: =G39-K39 -> -203 | Y39: =(H39/K39)-1 -> -0.13383459 | Z39: =(H39/J39)-1 -> -0.2109589
A40: Rabanitos | B40: Paquete | C40: 1 | D40: 800 | E40: 1350 | F40: =(E40-D40)/E40 -> 0.40740741 | G40: =D40*1.12 -> 896 | H40: =D40*1.08 -> 864 | I40: 1350 | J40: 990 | K40: 1450 | L40: =(J40-D40)/J40 -> 0.19191919 | M40: =(K40-D40)/K40 -> 0.44827586 | N40: 1990 | O40: =(E40-I40)/E40 -> 0 | P40: =(E40-K40)/E40 -> -0.074074074 | Q40: https://cdn.shopify.com/s/files/1/0733/7318/8148/files/Rabanito.jpg?v=1762370275 | R40: 1990 | S40: =VLOOKUP(A40,'precios semana 2906'!A:B,2,0) -> 800 | T40: =(S40/D40)-1 -> 0 | U40: =G40/I40-1 -> -0.3362963 | V40: =G40/K40-1 -> -0.38206897 | W40: =G40/J40-1 -> -0.094949495 | X40: =G40-K40 -> -554 | Y40: =(H40/K40)-1 -> -0.40413793 | Z40: =(H40/J40)-1 -> -0.12727273
...

Sheet Números
B2: Monto pedido mínimo
B3: Productos | C3: 15000 | D3: 15000 | E3: 40000
B4: Delivery bruto | C4: 2990 | D4: 3990 | E4: 0
A5: 0 | B5: Service Fee | C5: =C3*$A5 -> 0 | D5: =D3*$A5 -> 0 | E5: =E3*$A5 -> 0
B6: GOV Bruto | C6: =C3+C4+C5 -> 17990 | D6: =D3+D4+D5 -> 18990 | E6: =E3+E4+E5 -> 40000
B7: GOV Neto | C7: =C6/1.19 -> 15117.647 | D7: =D6/1.19 -> 15957.983 | E7: =E6/1.19 -> 33613.445
B9: Costos directos netos | C9: =SUM(C10:C15)*-1 -> -11998.876 | D9: =SUM(D10:D15)*-1 -> -12018.876 | E9: =SUM(E10:E15)*-1 -> -26504.202
A10: 0.39 | B10: Productos | C10: =C3/1.19*(1-$A10) -> 7689.0756 | D10: =D3/1.19*(1-$A10) -> 7689.0756 | E10: =E3/1.19*(1-$A10) -> 20504.202
B11: Picking | C11: 800 | D11: 800 | E11: 800
A12: 0 | B12: Packing | C12: 0 | D12: 0 | E12: 0
B13: Delivery | C13: 2400 | D13: 2400 | E13: 2400
A14: 0.05 | B14: Cashback (5%) | C14: =C3*$A14 -> 750 | D14: =D3*5% -> 750 | E14: =E3*5% -> 2000
A15: 0.02 | B15: Pasarela de pagos (2%) | C15: =C6*$A15 -> 359.8 | D15: =D6*2% -> 379.8 | E15: =E6*2% -> 800
B17: Margen neto $ | C17: =C7+C9 -> 3118.7714 | D17: =D7+D9 -> 3939.1076 | E17: =E7+E9 -> 7109.2437
B18: Margen neto % | C18: =C17/C3 -> 0.2079181 | D18: =D17/D3 -> 0.26260717 | E18: =E17/E3 -> 0.17773109

Sheet precios semana 2906
A1: Arandano | B1: 2000
A2: Frutillas | B2: 1600
A3: Frambuesa | B3: sin stock
A4: Higo | B4: sin stock
A5: Kiwi | B5: 1000
A6: Granada | B6: 1500
A7: Ciruela | B7: Borrar/ fuera de temp.
A8: Limon | B8: 700
A9: Limón sutil | B9: 1300
A10: Limon de pica | B10: 2000
A11: Mandarina | B11: 1200
A12: Mango | B12: 1300
A13: Manzana fuji | B13: 1900
A14: Manzana verde | B14: 1900
A15: Manzana pink lady | B15: 1900
A16: Mancaqui | B16: Borrar/ fuera de temp.
A17: Naranjas | B17: 1350
A18: Palta hass chilena | B18: 5800
A19: Palta hass peruana | B19: 4000
A20: Pera | B20: 1800
A21: Pepinodulce | B21: 2000
A22: Piña caramelo | B22: 3000
A23: Plátano | B23: 1400
A24: Platano peruano | B24: 1000
A25: Pomelo | B25: 900
A26: Tuna | B26: 2000
A27: Uva roja | B27: 1400
A28: Uva verde | B28: 2000
... A37: Apio | B37: 1400
A38: Alcachofas madrigal | B38: Sin stock
A39: Alcachofas españolas | B39: 800
A40: Berenjena | B40: 600
A41: Berros | B41: 700
A42: Betarraga | B42: 1000
A43: Brocoli | B43: 1400
A44: Brotes alfalfa | B44: Sin stock
A45: Brotes arveja | B45: Sin stock
A46: Bruselas | B46: 1200
A47: Camote Morado | B47: 1000
A48: Cebolla | B48: 250
...

Sheet Comparación
A1: Producto proveedor | B1: Unidad | C1: Lider (precio) | D1: Jumbo (precio) | E1: Juan Esparraguito (precio) | F1: Proxy de búsqueda | G1: Lider - producto encontrado (gramaje) | H1: Jumbo - producto encontrado (gramaje) | I1: Juan Esparraguito - producto encontrado (gramaje) | J1: Lider normalizado | K1: Jumbo normalizado | L1: Juan Esparraguito normalizado | M1: Juan esparraguito vs Jumbo (+31% promedio)
A2: Acelga | B2: Paquete | C2: 1490 | D2: 1590 | E2: no hay | F2: acelga | G2: Acelga Bolsa, 500 g | H2: Acelga 500 g | I2: no hay | J2: $2.980/kg | K2: $3.180/kg | L2: no hay | M2: =E2/D2-1 -> #VALUE!
A3: Ají amarillo (peruano) | B3: Kilo | C3: no hay | D3: no hay | E3: 1390 | F3: ají amarillo / peruano | G3: no hay | H3: no hay | I3: Ají Peruano (100 grs) | J3: no hay | K3: no hay | L3: $13.900/kg | M3: =E3/D3-1 -> #VALUE!
A4: Ají verde (infierno) | B4: Kilo | C4: 5390 | D4: 579 | E4: 590 | F4: ají verde | G4: Ají Verde Granel | H4: Ají Verde Granel | I4: Ají Verde (un) | J4: $5.390/kg | K4: $579/kg | L4: $590/un | M4: =E4/D4-1 -> 0.018998273
A5: Ajo | B5: Unidad | C5: 1090 | D5: 1190 | E5: =400*3 -> 1200 | F5: ajo | G5: Ajo en Malla, 3 Un | H5: Ajo 3 un. | I5: Ajo (un) | J5: $363/un | K5: $397/un | L5: $400/un | M5: =E5/D5-1 -> 0.0084033613
A6: Albahaca | B6: Kilo | C6: 1590 | D6: 1590 | E6: 1690 | F6: albahaca | G6: Albahaca Bolsa, 1 Un | H6: Albahaca 1 un. | I6: Albahaca | J6: $1.590/un | K6: $1.590/un | L6: $1.690/un | M6: =E6/D6-1 -> 0.062893082
A7: Alcachofas españolas | B7: Unidad | C7: 790 | D7: 790 | E7: 1290 | F7: alcachofa (cualquier variedad) | G7: Alcachofa Francesa, 1 Un | H7: Alcachofa Española 1 un. | I7: Alcachofa Española (un) | J7: $790/un | K7: $790/un | L7: $1.290/un | M7: =E7/D7-1 -> 0.63291139
A8: Almendras | B8: Kilo | C8: 14700 | D8: 14700 | E8: 15980 | F8: almendras | G8: no hay | H8: Almendras Naturales Granel | I8: no hay | J8: no hay | K8: $1.899/kg | L8: no hay | M8: =E8/D8-1 -> 0.08707483
A9: Almendras con chocolate | B9: Kilo | C9: no hay | D9: 4530 | E9: no hay | F9: almendras con chocolate | G9: no hay | H9: no hay | I9: no hay | J9: no hay | K9: no hay | L9: no hay | M9: =E9/D9-1 -> #VALUE!
A10: Aloe vera | B10: Kilo | C10: 2790 | D10: 2890 | E10: no hay | F10: aloe vera | G10: Aloe Vera Hoja, 1 Un | H10: Hoja Aloe Vera 1 un. | I10: no hay | J10: $2.790/un | K10: $2.890/un | L10: no hay | M10: =E10/D10-1 -> #VALUE!
A11: Apio | B11: Unidad | C11: 1000 | D11: 1490 | E11: 1990 | F11: apio | G11: Apio Mata Bolsa, 1 Un | H11: Apio Mata 1 un. | I11: Apio (un) | J11: $1.000/un | K11: $1.490/un | L11: $1.990/un | M11: =E11/D11-1 -> 0.33557047
A12: Arandano | B12: Kilo | C12: 2390 | D12: 2490 | E12: 10490 | F12: arándano | G12: Arándanos Importado Pote, 125 g | H12: Arándanos Pote 125 g | I12: Arándanos (250 grs) | J12: $19.120/kg | K12: $19.920/kg | L12: $41.960/kg | M12: =E12/D12-1 -> 3.2128514
A13: Avellanas europea | B13: Kilo | C13: no hay | D13: 1899 | E13: no hay | F13: avellana europea | G13: no hay | H13: Avellana Europea Granel | I13: no hay | J13: no hay | K13: $1.899/kg | L13: no hay | M13: =E13/D13-1 -> #VALUE!
A14: Berenjena | B14: Unidad | C14: 790 | D14: 790 | E14: 890 | F14: berenjena | G14: Berenjena Negra, 1 Un | H14: Berenjena 1 un. | I14: Berenjena (un) | J14: $790/un | K14: $790/un | L14: $890/un | M14: =E14/D14-1 -> 0.12658228
A15: Berros | B15: Kilo | C15: 1690 | D15: 1820 | E15: 2690 | F15: berro | G15: Berro Bolsa, 200 gr | H15: Berro Hidropónico 200 g | I15: Berros Hidropónicos (200 grs) | J15: $8.450/kg | K15: $9.100/kg | L15: $13.450/kg | M15: =E15/D15-1 -> 0.47802198
A16: Betarraga | B16: Paquete | C16: 1390 | D16: 1490 | E16: 2190 | F16: betarraga | G16: Betarraga Tubular Malla, 5 Un | H16: Betarraga Feria 5 un. | I16: Betarraga (4 un) | J16: $278/un | K16: $298/un | L16: $548/un | M16: =E16/D16-1 -> 0.46979866
A17: Brocoli | B17: Unidad | C17: 1090 | D17: 1590 | E17: 1990 | F17: brócoli | G17: Brócoli, 1 Un | H17: Brócoli Films 1 un. | I17: Brocoli (un) | J17: $1.090/un | K17: $1.590/un | L17: $1.990/un | M17: =E17/D17-1 -> 0.25157233
A18: Bruselas | B18: Kilo | C18: 3190 | D18: 3290 | E18: 2490 | F18: bruselas | G18: Brusela Malla, 500 gr | H18: Brusela 500 g | I18: Bruselas (500 grs) | J18: $6.380/kg | K18: $6.580/kg | L18: $4.980/kg | M18: =E18/D18-1 -> -0.24316109
A19: Camote Morado | B19: Kilo | C19: 3090 | D19: 1545 | E19: 1395 | F19: camote | G19: Camote Granel | H19: Camote Peruano Granel | I19: Papa Camote (2 un aprox) | J19: $3.090/kg | K19: $1.545/kg | L19: $698/un | M19: =E19/D19-1 -> -0.097087379
A20: Castañas de caju | B20: Kilo | C20: no hay | D20: 1899 | E20: no hay | F20: castañas de cajú | G20: no hay | H20: Castañas de Cajú Tostadas Sin Sal Granel | I20: no hay | J20: no hay | K20: $1.899/kg | L20: no hay | M20: =E20/D20-1 -> #VALUE!
A21: Cebolla | B21: Unidad | C21: 1550 | D21: 845 | E21: 795 | F21: cebolla | G21: Cebolla Granel. | H21: Cebolla Granel (1 a 2 un. Aprox) | I21: Cebolla (1 a 2 un aprox.) | J21: $1.550/kg | K21: $845/kg | L21: $398/un | M21: =E21/D21-1 -> -0.059171598
A22: Cebolla morada | B22: Unidad | C22: 1990 | D22: 995 | E22: 995 | F22: cebolla morada | G22: Cebolla Morada Malla, 1 Kg | H22: Cebolla Morada Granel | I22: Cebolla Morada (1 a 2 un aprox.) | J22: $1.990/kg | K22: $995/kg | L22: $498/un | M22: =E22/D22-1 -> 0
A23: Cebollín | B23: Paquete | C23: 1550 | D23: 850 | E23: 990 | F23: cebollín | G23: Cebollín Pack Bolsa, 6 Un | H23: Cebollín Feria 3 un. | I23: Cebollín (3 un) | J23: $258/un | K23: $283/un | L23: $330/un | M23: =E23/D23-1 -> 0.16470588
A24: Champiñon | B24: Bandeja | C24: 1590 | D24: 1650 | E24: 2190 | F24: champiñón blanco | G24: Champiñones Blanco Bandeja, 200 g | H24: Champiñón Bandeja 200 g | I24: Champiñón Blanco (200 grs) | J24: $7.950/kg | K24: $8.250/kg | L24: $10.950/kg | M24: =E24/D24-1 -> 0.32727273
A25: Chips de banana | B25: Kilo | C25: no hay | D25: 3990 | E25: no hay | F25: chips de banana | G25: no hay | H25: Banana Chips 400 g | I25: no hay | J25: no hay | K25: $9.975/kg | L25: no hay | M25: =E25/D25-1 -> #VALUE!
A26: Choclo americano | B26: Unidad | C26: 3590 | D26: 3700 | E26: 990 | F26: choclo | G26: Choclo Dulce Bandeja 4Un, 1 Un | H26: Choclo 4 un. | I26: Choclo Americano (un) | J26: $898/un | K26: $925/un | L26: $990/un | M26: =E26/D26-1 -> -0.73243243
A27: Ciboulette | B27: Paquete | C27: 690 | D27: 740 | E27: 790 | F27: ciboulette | G27: Ciboulette Bandeja, 20 g | H27: Ciboulette Display 20 g | I27: Ciboulette (20 grs) | J27: $34.500/kg | K27: $37.000/kg | L27: $39.500/kg | M27: =E27/D27-1 -> 0.067567568
A28: Cilantro | B28: Paquete | C28: 1390 | D28: 990 | E28: 1290 | F28: cilantro | G28: Cilantro Baby Pote, 60 gr | H28: Cilantro Paquete 120 g | I28: Cilantro Sanitizado (100 grs) | J28: $23.167/kg | K28: $8.250/kg | L28: $12.900/kg | M28: =E28/D28-1 -> 0.3030303
A29: Ciruela deshidratada | B29: Kilo | C29: no hay | D29: 4990 | E29: no hay | F29: ciruela deshidratada | G29: no hay | H29: Ciruelas Deshidratadas Pote 500 g | I29: no hay | J29: no hay | K29: $9.980/kg | L29: no hay | M29: =E29/D29-1 -> #VALUE!
A30: Coco en cubos | B30: Kilo | C30: no hay | D30: 1399 | E30: no hay | F30: coco (cubos/lonjas) | G30: no hay | H30: Coco en Lonjas Granel | I30: no hay | J30: no hay | K30: $1.399/kg | L30: no hay | M30: =E30/D30-1 -> #VALUE!
A31: Coco laminado | B31: Kilo | C31: no hay | D31: 1399 | E31: no hay | F31: coco laminado/lonjas | G31: no hay | H31: Coco en Lonjas Granel | I31: no hay | J31: no hay | K31: $1.399/kg | L31: no hay | M31: =E31/D31-1 -> #VALUE!
A32: Coco rallado | B32: Kilo | C32: no hay | D32: =1920*10 -> 19200 | E32: =2990*4 -> 11960 | F32: coco rallado | G32: no hay | H32: no hay | I32: no hay | J32: no hay | K32: no hay | L32: no hay | M32: =E32/D32-1 -> -0.37708333
A33: Coliflor | B33: Unidad | C33: 1590 | D33: 1690 | E33: 1990 | F33: coliflor | G33: Coliflor, 1 Un | H33: Coliflor Films 1 un. | I33: Coliflor (un) | J33: $1.590/un | K33: $1.690/un | L33: $1.990/un | M33: =E33/D33-1 -> 0.17751479
A34: Cranberries | B34: Kilo | C34: no hay | D34: 1299 | E34: no hay | F34: cranberries | G34: no hay | H34: Cranberries Mitad Granel | I34: no hay | J34: no hay | K34: $1.299/kg | L34: no hay | M34: =E34/D34-1 -> #VALUE!
A35: Dátiles | B35: Kilo | C35: no hay | D35: 4990 | E35: no hay | F35: dátiles | G35: no hay | H35: Dátil Sin Carozo 700 g | I35: no hay | J35: no hay | K35: $7.129/kg | L35: no hay | M35: =E35/D35-1 -> #VALUE!
A36: Diente de dragon | B36: Kilo | C36: 1990 | D36: 1790 | E36: no hay | F36: diente de dragón / pitahaya | G36: Diente de Dragón Bolsa, 1 Kg | H36: Diente de Dragón Granel | I36: no hay | J36: $1.990/kg | K36: $1.790/kg | L36: no hay | M36: =E36/D36-1 -> #VALUE!
A37: Esparragos | B37: Kilo | C37: no hay | D37: no hay | E37: no hay | F37: espárrago | G37: no hay | H37: no hay | I37: no hay | J37: no hay | K37: no hay | L37: no hay | M37: =E37/D37-1 -> #VALUE!
A38: Flor de hibiscos | B38: Kilo | C38: no hay | D38: no hay | E38: no hay | F38: flor de hibisco | G38: no hay | H38: no hay | I38: no hay | J38: no hay | K38: no hay | L38: no hay | M38: =E38/D38-1 -> #VALUE!
A39: Frutillas | B39: Kilo | C39: 2590 | D39: 2590 | E39: 4690 | F39: frutilla | G39: Frutillas Pote, 300 g | H39: Frutilla Pote 300 g | I39: Frutillas (500 grs) | J39: $8.633/kg | K39: $8.633/kg | L39: $9.380/kg | M39: =E39/D39-1 -> 0.81081081
A40: Goji | B40: Kilo | C40: no hay | D40: 1650 | E40: no hay | F40: goji | G40: no hay | H40: Goji 100 g | I40: no hay | J40: no hay | K40: $16.500/kg | L40: no hay | M40: =E40/D40-1 -> #VALUE!
...

Sheet Lider
A1: Nombre completo del producto | B1: Precio actual | C1: Url de la imagen | D1: Categoria | E1: Cantidad de medida | F1: Unidad
A2: Limón Malla, 1 kg | B2: 1950 | C2: https://i5.walmartimages.cl/asr/248bd1b1-37a4-464f-aa17-53104ebe63ac.7840608b4f5e2e75776c79060f2de2f4.jpeg?odnHeight=580&odnWidth=580&odnBg=FFFFFF | D2: Frutas | E2: 1 | F2: kilos
A3: Mandarina Malla, 1 kg | B3: 2000 | C3: https://i5.walmartimages.cl/asr/083eabb8-cd7f-46c2-ace0-8664f45a0cd8.906cbaffd69e0d8a60626c5fe9f8b7cb.jpeg?null=&odnHeight=580&odnWidth=580&odnBg=FFFFFF | D3: Frutas | E3: 1 | F3: kilos
A4: Manzana Royal Bolsa, 1 kg | B4: 1990 | C4: https://i5.walmartimages.cl/asr/87055fe6-e907-4a58-8677-0563ee63c3d1.2bb397d62720c4a73ec62b5bc6edd4f3.jpeg?odnHeight=580&odnWidth=580&odnBg=FFFFFF | D4: Frutas | E4: 1 | F4: kilos
A5: Manzana Verde Bolsa, 1 kg | B5: 1990 | C5: https://i5.walmartimages.cl/asr/26816f7e-4d05-463b-b73e-cd6f05220db8.a49fa7c44acb5d70eadb6d39e4a02ddd.jpeg?odnHeight=580&odnWidth=580&odnBg=FFFFFF | D5: Frutas | E5: 1 | F5: kilos
A6: Palta Hass Chilena Granel | B6: 6290 | C6: https://i5.walmartimages.cl/asr/c1231a68-55a7-4c9e-9f6f-35163325a1d0.a02a9ad32ba8f2ea5afbffbeafce3d6d.jpeg?odnHeight=580&odnWidth=580&odnBg=FFFFFF | D6: Frutas | E6: 1 | F6: kilos
A7: Plátano Granel | B7: 1450 | C7: https://i5.walmartimages.cl/asr/c1a030d6-88b6-44fb-9fe1-f5374fcdf51e.0431f1fccec368ba6a244b84b17e5b01.jpeg?odnHeight=580&odnWidth=580&odnBg=FFFFFF | D7: Frutas | E7: 1 | F7: kilos
A8: Manzana Fuji Granel. | B8: 2490 | C8: https://i5.walmartimages.cl/asr/aaf18678-bd4f-4e39-8f25-582207e7d87d.1713ece21412bcf8549cfdd3877aa35a.jpeg?odnHeight=580&odnWidth=580&odnBg=FFFFFF | D8: Frutas | E8: 1 | F8: kilos
A9: Frutillas Pote, 300 g | B9: 2590 | C9: https://i5.walmartimages.cl/asr/3eb1e73d-5fc6-4d43-87c6-590c56eb24a2.1c2d56a033728a5ab87d862c2ce0ae61.jpeg?odnHeight=580&odnWidth=580&odnBg=FFFFFF | D9: Frutas | E9: 300 | F9: gramos
A10: Naranja Importada Granel | B10: 2790 | C10: https://i5.walmartimages.cl/asr/7cec853e-fb16-4a48-9eec-c763cee05513.cf714b9536fcc0d6ea89e1eee7afe81a.jpeg?odnHeight=580&odnWidth=580&odnBg=FFFFFF | D10: Frutas | E10: 1 | F10: kilos
A11: Naranja Malla, 2 kg | B11: 3590 | C11: https://i5.walmartimages.cl/asr/49eac9c8-a6ab-49fb-8b03-978ccd8ab53c.fd750cbb4b081ea4cb169b99a94d0f4c.jpeg?odnHeight=580&odnWidth=580&odnBg=FFFFFF | D11: Frutas | E11: 2 | F11: kilos
A12: Mango Granel | B12: 2890 | C12: https://i5.walmartimages.cl/asr/09467583-8b9c-4d63-b52b-bf7d3828704a.91674db31600eb4eb8bb0d34699b672e.jpeg?odnHeight=580&odnWidth=580&odnBg=FFFFFF | D12: Frutas | E12: 1 | F12: kilos
A13: Kiwi Granel | B13: 4190 | C13: https://i5.walmartimages.cl/asr/a3ff5ea4-0eea-4483-9d33-8bef94fa9ebc.78ebe29f03a715ed65a2cfc62ab6d095.jpeg?odnHeight=580&odnWidth=580&odnBg=FFFFFF | D13: Frutas | E13: 1 | F13: kilos
... A21: Pomelo Granel | B21: 2150 | C21: https://i5.walmartimages.cl/asr/20df7f10-f765-47be-9147-9dbc72e5d56f.2b926841f31184654a8b84c90873c27b.jpeg?odnHeight=580&odnWidth=580&odnBg=FFFFFF | D21: Frutas | E21: 1 | F21: kilos
A22: Mix de Frutas (Manzanas, naranjas y Peras) Bolsa, 1,5 kg | B22: 2190 | C22: https://i5.walmartimages.cl/asr/e3df83ee-22d4-4354-a8d5-b575c62aab3c.6388bb26100f035705c1cbd655803392.jpeg?odnHeight=580&odnWidth=580&odnBg=FFFFFF | D22: Frutas | E22: 1,5 | F22: kilos
A23: Manzana Fuji Bolsa., 1 kg | B23: 1990 | C23: https://i5.walmartimages.cl/asr/a1171bcc-9ed2-48fe-935e-e09d4e7c6622.635d05bd27937258640b697749e2dddf.jpeg?odnHeight=580&odnWidth=580&odnBg=FFFFFF | D23: Frutas | E23: 1 | F23: kilos
A24: Pepino Dulce Granel | B24: 3290 | C24: https://i5.walmartimages.cl/asr/f0e61f15-8f9f-4617-90fb-692827840f9f.94b758636bcafa818ae67e3eb1c5bc88.jpeg?odnHeight=580&odnWidth=580&odnBg=FFFFFF | D24: Frutas | E24: 1 | F24: kilos
A25: Arándanos Importado Pote, 125 g | B25: 2390 | C25: https://i5.walmartimages.cl/asr/83aed111-738b-4da4-8ec2-bd0d276a88bf.e427a0a7d8d2fd2e7853f16c3ddf39c7.jpeg?odnHeight=580&odnWidth=580&odnBg=FFFFFF | D25: Frutas | E25: 125 | F25: gramos
A26: Manzana Verde Granel. | B26: 2490 | C26: https://i5.walmartimages.cl/asr/ec8c8ad9-0518-4d8a-8f2b-6954e34fcde5.8431f0f3a2a78283f3f579bd931c629f.jpeg?odnHeight=580&odnWidth=580&odnBg=FFFFFF | D26: Frutas | E26: 1 | F26: kilos
A27: Limón Sutil Malla, 1 kg | B27: 3650 | C27: https://i5.walmartimages.cl/asr/6e91773b-2219-416f-be21-571d2a150a59.93b3dc03226d82221f635e108c4a882f.jpeg?odnHeight=580&odnWidth=580&odnBg=FFFFFF | D27: Frutas | E27: 1 | F27: kilos
A28: Limón Granel | B28: 1950 | C28: https://i5.walmartimages.cl/asr/b4883972-a340-4960-b082-80df64a5e6f1.d11cccdf2d520234e7c34584c4715701.jpeg?odnHeight=580&odnWidth=580&odnBg=FFFFFF | D28: Frutas | E28: 1 | F28: kilos
A29: Pera Packams Granel | B29: 2150 | C29: https://i5.walmartimages.cl/asr/241bd205-b6b9-429b-b68b-91c78ef59c8a.96082974a4b67edc985e53ec84efe4b2.jpeg?odnHeight=580&odnWidth=580&odnBg=FFFFFF | D29: Frutas | E29: 1 | F29: kilos
A30: Frutillas Pote, 500 g | B30: 3190 | C30: https://i5.walmartimages.cl/asr/3f93ee9f-29e1-4ec6-9357-623c62793713.a6641a8ae20a6bd07255e02fbabe9faf.jpeg?odnHeight=580&odnWidth=580&odnBg=FFFFFF | D30: Frutas | E30: 500 | F30: gramos
A31: Arándano Pote, 300 g | B31: 4090 | C31: https://i5.walmartimages.cl/asr/93895a7e-108f-466b-b076-6e0e83282232.6a18620121058c55c18f6cc2d69fffbf.jpeg?null=&odnHeight=580&odnWidth=580&odnBg=FFFFFF | D31: Frutas | E31: 300 | F31: gramos
A32: Granada Granel | B32: 4490 | C32: https://i5.walmartimages.cl/asr/9b694b29-44c2-49b4-a997-4625bc2f8e1e.0e64d26c7dd4a11eed203d828c7d41e6.jpeg?null=&odnHeight=580&odnWidth=580&odnBg=FFFFFF | D32: Frutas | E32: 1 | F32: kilos
A33: Kiwi Amarillo Pote, 500 g | B33: 2790 | C33: https://i5.walmartimages.cl/asr/a5564f5c-8c35-418a-9808-2eccef53bac1.55449767a32f5445560d29a9f6b961c7.jpeg?odnHeight=580&odnWidth=580&odnBg=FFFFFF | D33: Frutas | E33: 500 | F33: gramos
A34: Plátano Barraganete Granel | B34: 1450 | C34: https://i5.walmartimages.cl/asr/67639522-2e1b-41fd-8415-a18342dfe374.8a23b5eaae7fc2f4cac9602954828cd9.jpeg?odnHeight=580&odnWidth=580&odnBg=FFFFFF | D34: Frutas | E34: 1 | F34: kilos
A35: Mandarina Sofruco Malla, 1,5 kg | B35: 4990 | C35: https://i5.walmartimages.cl/asr/bc84d819-d9d4-4af2-9c5c-0f78e499a10a.df7cea40eebf648c19df2e1cc034f7a5.jpeg?odnHeight=580&odnWidth=580&odnBg=FFFFFF | D35: Frutas | E35: 1,5 | F35: kilos
A36: Pera Abate Granel. | B36: 2150 | C36: https://i5.walmartimages.cl/asr/020d1058-f205-4af2-9132-a3ad49f232c0.0e34653ea39927e158544b800d928ecd.jpeg?odnHeight=580&odnWidth=580&odnBg=FFFFFF | D36: Frutas | E36: 1 | F36: kilos
A37: Plátano Baby Orito Granel | B37: 2000 | C37: https://i5.walmartimages.cl/asr/f4170aac-aa5d-4d07-a018-0570ef72d9e1.77714a1d8f5693d3af642554f47f9af6.jpeg?odnHeight=580&odnWidth=580&odnBg=FFFFFF | D37: Frutas | E37: 1 | F37: kilos
A38: Limón Sin Semillas Malla, 900 g | B38: 1990 | C38: https://i5.walmartimages.cl/asr/122b0b25-3f2a-4665-872e-848f663caec7.dfd1e39ba1fac8248edf239f49a943e4.jpeg?odnHeight=580&odnWidth=580&odnBg=FFFFFF | D38: Frutas | E38: 900 | F38: gramos
A39: Frambuesas Pote, 70 g | B39: 1990 | C39: https://i5.walmartimages.cl/asr/45bef92f-1d02-45c8-9603-18d9a9cab63d.d1c55c070f1545f75f9162a65148a3e2.jpeg?odnHeight=580&odnWidth=580&odnBg=FFFFFF | D39: Frutas | E39: 70 | F39: gramos
A40: Tuna Malla, 1 kg | B40: 2890 | C40: https://i5.walmartimages.cl/asr/f454eabc-a704-4051-9cc2-61ae3a9ea708.bced8adf7ec553a8090f89307c2c1209.jpeg?odnHeight=580&odnWidth=580&odnBg=FFFFFF | D40: Frutas | E40: 1 | F40: kilos
A41: Tuna Granel | B41: 3290 | C41: https://i5.walmartimages.cl/asr/945e5518-2a01-460c-ab47-0bbc57535333.a3085046531cd30670182a88928b43d3.jpeg?odnHeight=580&odnWidth=580&odnBg=FFFFFF | D41: Frutas | E41: 1 | F41: kilos
A42: Membrillo Granel | B42: 2490 | C42: https://i5.walmartimages.cl/asr/f5c7878d-2051-4bdf-9def-f0c742aa2f05.c70df7278aaa19bb79c3b753ced98cbf.jpeg?null=&odnHeight=580&odnWidth=580&odnBg=FFFFFF | D42: Frutas | E42: 1 | F42: kilos
A43: Manzana Roja Bolsa, 1 kg | B43: 1990 | C43: https://i5.walmartimages.cl/asr/9be25181-4fa4-4d4c-80ec-78a6cdb3e21f.78b8b6dd7091ae87f32c369b6899146f.jpeg?odnHeight=580&odnWidth=580&odnBg=FFFFFF | D43: Frutas | E43: 1 | F43: kilos
A44: Pomelo Malla, 2 kg | B44: 3590 | C44: https://i5.walmartimages.cl/asr/f732e2ee-6e52-47fd-a2c8-668b3f55be61.5c1b0adbe47499e39fe12b0cd35e03c3.jpeg?odnHeight=580&odnWidth=580&odnBg=FFFFFF | D44: Frutas | E44: 2 | F44: kilos
A45: Palta Negra La Cruz Malla, 1 kg | B45: 4490 | C45: https://i5.walmartimages.cl/asr/0dbee476-6ddb-4f2d-ae73-eb68608d1add.730bf0363fd9c98703bad21f801acea4.jpeg?odnHeight=580&odnWidth=580&odnBg=FFFFFF | D45: Frutas | E45: 1 | F45: kilos
A46: Manzana Pink Lady Bolsa, 1 kg | B46: 1890 | C46: https://i5.walmartimages.cl/asr/c2e7395a-5e45-40b6-bd41-8d4be8612e31.e7293d2995edcc31407df3b2f1a6e7df.jpeg?null=&odnHeight=580&odnWidth=580&odnBg=FFFFFF | D46: Frutas | E46: 1 | F46: kilos
A47: Castaña Granel | B47: 4990 | C47: https://i5.walmartimages.cl/asr/6605b742-d7b3-4e0d-8b71-a0fc353af7dd.e5785c7e01ae4cde1b8e5beb78894825.jpeg?null=&odnHeight=580&odnWidth=580&odnBg=FFFFFF | D47: Frutas | E47: 1 | F47: kilos
...

Sheet Jumbo
A1: Nombre completo del producto | B1: Precio actual | C1: Url de la imagen | D1: Categoria | E1: Cantidad de medida | F1: Unidad
A2: Nectarín Importado Granel | B2: 3995 | C2: https://jumbocl.vteximg.com.br/arquivos/ids/352981-250-250/977515.jpg?v=638776695489130000 | D2: Frutas | E2: 1 | F2: kilos
A3: Plátano Extra Granel (1 a 2 un. Aprox) | B3: 795 | C3: https://jumbocl.vteximg.com.br/arquivos/ids/350892-250-250/Platano-granel.jpg?v=638776683161100000 | D3: Frutas | E3: 1 | F3: kilos
A4: Palta Hass Extra Chilena (2 un. Aprox) | B4: 3245 | C4: https://jumbocl.vteximg.com.br/arquivos/ids/348021-250-250/Palta-Hass-Extra-Chilena-granel.jpg?v=638784526059170000 | D4: Verduras | E4: 2 | F4: unidad
A5: Papa Malla 2 kg | B5: 2590 | C5: https://jumbocl.vteximg.com.br/arquivos/ids/348025-250-250/Papa-malla-2-kg.jpg?v=638776479317000000 | D5: Verduras | E5: 2 | F5: kilos
A6: Limón Malla 1 kg | B6: 1590 | C6: https://jumbocl.vteximg.com.br/arquivos/ids/348018-250-250/Limon-malla-1-kg.jpg?v=638776479219900000 | D6: Verduras | E6: 1 | F6: kilos
A7: Palta Hass Malla 1 kg | B7: 2890 | C7: https://jumbocl.vteximg.com.br/arquivos/ids/348022-250-250/Palta-hass-malla-1-kg.jpg?v=638776479276530000 | D7: Verduras | E7: 1 | F7: kilos
A8: Zanahoria Bolsa 1 kg | B8: 1350 | C8: https://jumbocl.vteximg.com.br/arquivos/ids/348051-250-250/Zanahoria-bolsa-1-kg.jpg?v=638776479671400000 | D8: Verduras | E8: 1 | F8: kilos
A9: Champiñón Bandeja 200 g | B9: 1650 | C9: https://jumbocl.vteximg.com.br/arquivos/ids/355100-250-250/Champi%C3%B1on-bandeja-200-g.jpg?v=638776705195000000 | D9: Verduras | E9: 200 | F9: gramos
A10: Zapallo Italiano 1 un. | B10: 790 | C10: https://jumbocl.vteximg.com.br/arquivos/ids/348057-250-250/Zapallo-italiano-un.jpg?v=638776479756130000 | D10: Verduras | E10: 1 | F10: unidad
A11: Tomate Larga Vida Granel (1 a 2 un. Aprox) | B11: 995 | C11: https://jumbocl.vteximg.com.br/arquivos/ids/297810-250-250/Tomate-granel.jpg?v=638775743642170000 | D11: Verduras | E11: 1 | F11: kilos
A12: Pepino Ensalada 1 un. | B12: 750 | C12: https://jumbocl.vteximg.com.br/arquivos/ids/348029-250-250/Pepino-ensalada-un.jpg?v=638776479365130000 | D12: Verduras | E12: 1 | F12: unidad
A13: Brócoli Films 1 un. | B13: 1590 | C13: https://jumbocl.vteximg.com.br/arquivos/ids/347994-250-250/Brocoli-films-un.jpg?v=638776478878200000 | D13: Verduras | E13: 1 | F13: unidad
... A123: Ajo 2 un. | B123: 1090 | C123: https://jumbocl.vteximg.com.br/arquivos/ids/353019-250-250/Ajo-2-un.jpg?v=638776695668300000 | D123: Verduras | E123: 2 | F123: unidad
A124: Mandarina Bolsa 1.5 kg | B124: 6990 | C124: https://jumbocl.vteximg.com.br/arquivos/ids/366686-250-250/Mandarina-bolsa-15-kg.jpg?v=638776764261130000 | D124: Frutas | E124: 1,5 | F124: kilos
A125: Tomate Hidropónico Racimo Granel | B125: 1245 | C125: https://jumbocl.vteximg.com.br/arquivos/ids/348044-250-250/261265-KG.jpg?v=638776479549630000 | D125: Verduras | E125: 1 | F125: kilos
A126: Cebolla Crujiente Ligeramente Salada 80 g | B126: 2490 | C126: https://jumbocl.vteximg.com.br/arquivos/ids/502890-250-250/Cebolla-Crujiente-Ligeramente-Salada-80-g.jpg?v=638924452010370000 | D126: Verduras | E126: 80 | F126: gramos
A127: Spring Mix Dole 150 g | B127: 3890 | C127: https://jumbocl.vteximg.com.br/arquivos/ids/347920-250-250/Spring-mix-Dole-150-g.jpg?v=638776477883670000 | D127: Verduras | E127: 150 | F127: gramos
A128: Corazones de Apio Dole 2 un. | B128: 3210 | C128: https://jumbocl.vteximg.com.br/arquivos/ids/353163-250-250/Corazones-de-Apio-Dole-2-unid.jpg?v=638776696231330000 | D128: Verduras | E128: 2 | F128: unidad
A129: Plátano Barraganette Granel | B129: 995 | C129: https://jumbocl.vteximg.com.br/arquivos/ids/347946-250-250/Platano-Barraganette-granel.jpg?v=638776478245070000 | D129: Frutas | E129: 1 | F129: kilos
A130: Salad Kit Coleslaw 300 g | B130: 2690 | C130: https://jumbocl.vteximg.com.br/arquivos/ids/445447-250-250/Salad-Kit-Coleslaw-300-g.jpg?v=638839631379530000 | D130: Verduras | E130: 300 | F130: gramos
A131: Ensalada Dole Apio 420 g | B131: 2390 | C131: https://jumbocl.vteximg.com.br/arquivos/ids/347909-250-250/Ensalada-apio-Dole-420-g.jpg?v=638776477738800000 | D131: Verduras | E131: 420 | F131: gramos
